Workbook

Sheet Assumptions
A2: This is my personal work that I have built for Practice on my Financial Modelling Skills | I2: PROJECT SUMMARY
B3: Below are All the Assumptions used in this Model Creation for the Project | I3: A US - Based 5-Star hotel, Hot Platters Group which currently operates in different states in the US
I4: needs to open up another one of its own branch in Kenya to due to the rising demand of hospitality services
B5: Start Date: | C5: 43951 | I5: in the country and more specifically in Nairobi. Before setting up the business, Hot Platters Group
B6: Construction Period: | C6: 3 Months | I6: wants to be sure that opening up a branch in Nairobi will be profitable
B7: End Date: | C7: 44013
A8: Amounts in KSh. | I8: The assumptions on the left have been provided by the Research and Development Team to create a
I9: financial model which will be forwarded to top management of the Group to enable wise decision
A10: Restaurant Construction - 3 Months | I10: making on the new Investment Venture
A12: Start Date | G12: 43951 | I12: Your Task: Create the Business Financial Model that will be forwarded to the top management of the Group
A13: Construction Period | G13: 3 Months
A14: End Date | G14: 44013
A16: Revenue
A17: Particulars | B17: Weekdays | C17: Weekends | E17: Particulars | F17: Weekdays | G17: Weekends
A18: Lunch | E18: Dinner
A19: APC | B19: 1500 | C19: 1700 | E19: APC | F19: 1600 | G19: 1900
A20: Alcoholic Beverages | B20: 300 | C20: 500 | E20: Alcoholic Beverages | F20: 400 | G20: 650
A21: Non-Alcoholic Bevarages | B21: 200 | C21: 200 | E21: Non-Alcoholic Bevarages | F21: 200 | G21: 250
A22: Food | B22: 1000 | C22: 1000 | E22: Food | F22: 1000 | G22: 1000
A23: Y-O-Y Growth Price Rate | B23: 0.05 | C23: 0.05 | E23: Y-O-Y Growth Price Rate | F23: 0.05 | G23: 0.05
A25: Occupancy | E25: Occupancy
A26: No. of Covers Available | B26: 100 | C26: 100 | E26: No. of Covers Available | F26: 100 | G26: 100
A27: No. of Rounds Available | B27: 2 | C27: 2 | E27: No. of Rounds Available | F27: 2 | G27: 2
A28: No. of Covers Occupied/Round | B28: 10 | C28: 13 | E28: No. of Covers Occupied/Round | F28: 13 | G28: 15
A29: MoM Growth | B29: 0.02 | C29: 0.04 | E29: MoM Growth | F29: 0.02 | G29: 0.04
A30: Max Occupancy/Round | B30: 60 | C30: 80 | E30: Max Occupancy/Round | F30: 70 | G30: 90
A33: Direct Expenses
A34: Alcoholic Beverage Cost (% of Revenue | D34: 0.35
A35: Non Alcoholic Beverage Cost (% of Revenue) | D35: 0.4
A36: Food Cost (% of Revenue) | D36: 0.3
A39: Salary
A40: Members Team | B40: No. of Employees | C40: Salary/M | D40: Salary/M
A41: Receptionist | B41: 2 | C41: 20000 | D41: 40000
A42: Restaurants Mnager | B42: 2 | C42: 50000 | D42: 100000
A43: Waiters | B43: 10 | C43: 20000 | D43: 200000
A44: Head Chef | B44: 1 | C44: 100000 | D44: 100000
A45: Chefs | B45: 2 | C45: 75000 | D45: 150000
A46: Ass Chef | B46: 6 | C46: 30000 | D46: 180000
A47: Valet Parking | B47: 3 | C47: 17000 | D47: 51000
A48: Cleaners | B48: 5 | C48: 17000 | D48: 85000
...

Sheet Monthly Revenue
I2: Monthly Revenue
A4: All Values in: | B4: KSh
E5: 1 | F5: =E5+1 -> 2 | G5: =F5+1 -> 3 | H5: =G5+1 -> 4 | I5: =H5+1 -> 5 | J5: =I5+1 -> 6 | K5: =J5+1 -> 7 | L5: =K5+1 -> 8 | M5: =L5+1 -> 9 | ... AN5: =AM5+1 -> 36
E6: =EOMONTH(Assumptions!C5,0) -> 43951 | F6: =EOMONTH(E6,1) -> 43982 | G6: =EOMONTH(F6,1) -> 44012 | H6: =EOMONTH(G6,1) -> 44043 | I6: =EOMONTH(H6,1) -> 44074 | J6: =EOMONTH(I6,1) -> 44104 | K6: =EOMONTH(J6,1) -> 44135 | L6: =EOMONTH(K6,1) -> 44165 | M6: =EOMONTH(L6,1) -> 44196 | ... AN6: =EOMONTH(AM6,1) -> 45016
A7: Operating Days | E7: 0 | F7: 0 | G7: 0 | H7: 31 | I7: 31 | J7: 30 | K7: 31 | L7: 30 | M7: 31 | N7: 31 | O7: 28 | P7: 31 | Q7: 30 | R7: 31 | S7: 30 | T7: 31 | U7: 31 | V7: 30 | W7: 31 | X7: 30 | Y7: 31 | Z7: 31 | AA7: 28 | AB7: 31 | AC7: 30 | AD7: 31 | AE7: 30 | AF7: 31 | AG7: 31 | AH7: 30 | AI7: 31 | AJ7: 30 | AK7: 31 | AL7: 31 | AM7: 28 | AN7: 31
A8: No. of Weekdays in a Month | E8: =IF(E7>0,NETWORKDAYS(D6+1,E6),0) -> 0 | F8: =IF(F7>0,NETWORKDAYS(E6+1,F6),0) -> 0 | G8: =IF(G7>0,NETWORKDAYS(F6+1,G6),0) -> 0 | H8: =IF(H7>0,NETWORKDAYS(G6+1,H6),0) -> 23 | I8: =IF(I7>0,NETWORKDAYS(H6+1,I6),0) -> 21 | J8: =IF(J7>0,NETWORKDAYS(I6+1,J6),0) -> 22 | K8: =IF(K7>0,NETWORKDAYS(J6+1,K6),0) -> 22 | L8: =IF(L7>0,NETWORKDAYS(K6+1,L6),0) -> 21 | ... AN8: =IF(AN7>0,NETWORKDAYS(AM6+1,AN6),0) -> 23
A9: No. of Weekends in a Month | E9: =E7-E8 -> 0 | F9: =F7-F8 -> 0 | G9: =G7-G8 -> 0 | H9: =H7-H8 -> 8 | I9: =I7-I8 -> 10 | J9: =J7-J8 -> 8 | K9: =K7-K8 -> 9 | L9: =L7-L8 -> 9 | ... AN9: =AN7-AN8 -> 8
A11: No. of Guests
A12: Weekdays
A13: Lunch | E13: =IF(E$8>0,MIN(MAX(Assumptions!$B$28*Assumptions!$B$27,'Monthly Revenue'!D13*(1+Assumptions!$B$29)),Assumptions!$B$30),0) -> 0 | F13: =IF(F$8>0,MIN(MAX(Assumptions!$B$28*Assumptions!$B$27,'Monthly Revenue'!E13*(1+Assumptions!$B$29)),Assumptions!$B$30),0) -> 0 | G13: =IF(G$8>0,MIN(MAX(Assumptions!$B$28*Assumptions!$B$27,'Monthly Revenue'!F13*(1+Assumptions!$B$29)),Assumptions!$B$30),0) -> 0 | H13: =IF(H$8>0,MIN(MAX(Assumptions!$B$28*Assumptions!$B$27,'Monthly Revenue'!G13*(1+Assumptions!$B$29)),Assumptions!$B$30),0) -> 20 | I13: =IF(I$8>0,MIN(MAX(Assumptions!$B$28*Assumptions!$B$27,'Monthly Revenue'!H13*(1+Assumptions!$B$29)),Assumptions!$B$30),0) -> 20.4 | J13: =IF(J$8>0,MIN(MAX(Assumptions!$B$28*Assumptions!$B$27,'Monthly Revenue'!I13*(1+Assumptions!$B$29)),Assumptions!$B$30),0) -> 20.808 | K13: =IF(K$8>0,MIN(MAX(Assumptions!$B$28*Assumptions!$B$27,'Monthly Revenue'!J13*(1+Assumptions!$B$29)),Assumptions!$B$30),0) -> 21.22416 | L13: =IF(L$8>0,MIN(MAX(Assumptions!$B$28*Assumptions!$B$27,'Monthly Revenue'!K13*(1+Assumptions!$B$29)),Assumptions!$B$30),0) -> 21.648643 | ... AN13: =IF(AN$8>0,MIN(MAX(Assumptions!$B$28*Assumptions!$B$27,'Monthly Revenue'!AM13*(1+Assumptions!$B$29)),Assumptions!$B$30),0) -> 37.690812
A14: Dinner | E14: =IF(E$8>0,MIN(MAX(Assumptions!$F$28*Assumptions!$F$27,'Monthly Revenue'!D14*(1+Assumptions!$F$29)),Assumptions!$F$30),0) -> 0 | F14: =IF(F$8>0,MIN(MAX(Assumptions!$F$28*Assumptions!$F$27,'Monthly Revenue'!E14*(1+Assumptions!$F$29)),Assumptions!$F$30),0) -> 0 | G14: =IF(G$8>0,MIN(MAX(Assumptions!$F$28*Assumptions!$F$27,'Monthly Revenue'!F14*(1+Assumptions!$F$29)),Assumptions!$F$30),0) -> 0 | H14: =IF(H$8>0,MIN(MAX(Assumptions!$F$28*Assumptions!$F$27,'Monthly Revenue'!G14*(1+Assumptions!$F$29)),Assumptions!$F$30),0) -> 26 | I14: =IF(I$8>0,MIN(MAX(Assumptions!$F$28*Assumptions!$F$27,'Monthly Revenue'!H14*(1+Assumptions!$F$29)),Assumptions!$F$30),0) -> 26.52 | J14: =IF(J$8>0,MIN(MAX(Assumptions!$F$28*Assumptions!$F$27,'Monthly Revenue'!I14*(1+Assumptions!$F$29)),Assumptions!$F$30),0) -> 27.0504 | K14: =IF(K$8>0,MIN(MAX(Assumptions!$F$28*Assumptions!$F$27,'Monthly Revenue'!J14*(1+Assumptions!$F$29)),Assumptions!$F$30),0) -> 27.591408 | L14: =IF(L$8>0,MIN(MAX(Assumptions!$F$28*Assumptions!$F$27,'Monthly Revenue'!K14*(1+Assumptions!$F$29)),Assumptions!$F$30),0) -> 28.143236 | ... AN14: =IF(AN$8>0,MIN(MAX(Assumptions!$F$28*Assumptions!$F$27,'Monthly Revenue'!AM14*(1+Assumptions!$F$29)),Assumptions!$F$30),0) -> 48.998055
A16: Weekends
A17: Lunch | E17: =IF(E$8>0,MIN(MAX(Assumptions!$C$28*Assumptions!$C$27,'Monthly Revenue'!D17*(1+Assumptions!$C$29)),Assumptions!$C$30),0) -> 0 | F17: =IF(F$8>0,MIN(MAX(Assumptions!$C$28*Assumptions!$C$27,'Monthly Revenue'!E17*(1+Assumptions!$C$29)),Assumptions!$C$30),0) -> 0 | G17: =IF(G$8>0,MIN(MAX(Assumptions!$C$28*Assumptions!$C$27,'Monthly Revenue'!F17*(1+Assumptions!$C$29)),Assumptions!$C$30),0) -> 0 | H17: =IF(H$8>0,MIN(MAX(Assumptions!$C$28*Assumptions!$C$27,'Monthly Revenue'!G17*(1+Assumptions!$C$29)),Assumptions!$C$30),0) -> 26 | I17: =IF(I$8>0,MIN(MAX(Assumptions!$C$28*Assumptions!$C$27,'Monthly Revenue'!H17*(1+Assumptions!$C$29)),Assumptions!$C$30),0) -> 27.04 | J17: =IF(J$8>0,MIN(MAX(Assumptions!$C$28*Assumptions!$C$27,'Monthly Revenue'!I17*(1+Assumptions!$C$29)),Assumptions!$C$30),0) -> 28.1216 | K17: =IF(K$8>0,MIN(MAX(Assumptions!$C$28*Assumptions!$C$27,'Monthly Revenue'!J17*(1+Assumptions!$C$29)),Assumptions!$C$30),0) -> 29.246464 | L17: =IF(L$8>0,MIN(MAX(Assumptions!$C$28*Assumptions!$C$27,'Monthly Revenue'!K17*(1+Assumptions!$C$29)),Assumptions!$C$30),0) -> 30.416323 | ... AN17: =IF(AN$8>0,MIN(MAX(Assumptions!$C$28*Assumptions!$C$27,'Monthly Revenue'!AM17*(1+Assumptions!$C$29)),Assumptions!$C$30),0) -> 80
A18: Dinner | E18: =IF(E$8>0,MIN(MAX(Assumptions!$G$28*Assumptions!$G$27,'Monthly Revenue'!D18*(1+Assumptions!$G$29)),Assumptions!$G$30),0) -> 0 | F18: =IF(F$8>0,MIN(MAX(Assumptions!$G$28*Assumptions!$G$27,'Monthly Revenue'!E18*(1+Assumptions!$G$29)),Assumptions!$G$30),0) -> 0 | G18: =IF(G$8>0,MIN(MAX(Assumptions!$G$28*Assumptions!$G$27,'Monthly Revenue'!F18*(1+Assumptions!$G$29)),Assumptions!$G$30),0) -> 0 | H18: =IF(H$8>0,MIN(MAX(Assumptions!$G$28*Assumptions!$G$27,'Monthly Revenue'!G18*(1+Assumptions!$G$29)),Assumptions!$G$30),0) -> 30 | I18: =IF(I$8>0,MIN(MAX(Assumptions!$G$28*Assumptions!$G$27,'Monthly Revenue'!H18*(1+Assumptions!$G$29)),Assumptions!$G$30),0) -> 31.2 | J18: =IF(J$8>0,MIN(MAX(Assumptions!$G$28*Assumptions!$G$27,'Monthly Revenue'!I18*(1+Assumptions!$G$29)),Assumptions!$G$30),0) -> 32.448 | K18: =IF(K$8>0,MIN(MAX(Assumptions!$G$28*Assumptions!$G$27,'Monthly Revenue'!J18*(1+Assumptions!$G$29)),Assumptions!$G$30),0) -> 33.74592 | L18: =IF(L$8>0,MIN(MAX(Assumptions!$G$28*Assumptions!$G$27,'Monthly Revenue'!K18*(1+Assumptions!$G$29)),Assumptions!$G$30),0) -> 35.095757 | ... AN18: =IF(AN$8>0,MIN(MAX(Assumptions!$G$28*Assumptions!$G$27,'Monthly Revenue'!AM18*(1+Assumptions!$G$29)),Assumptions!$G$30),0) -> 90
A20: APC
A21: Weekdays
A22: Lunch
A23: Alcoholic Beverages | H23: =Assumptions!B20 -> 300 | I23: =H23 -> 300 | J23: =I23 -> 300 | K23: =J23 -> 300 | L23: =K23 -> 300 | M23: =L23 -> 300 | N23: =M23 -> 300 | O23: =N23 -> 300 | P23: =O23 -> 300 | ... S23: =R23 -> 300 | T23: =S23*(1+Assumptions!$B$23) -> 315 | U23: =T23 -> 315 | V23: =U23 -> 315 | W23: =V23 -> 315 | X23: =W23 -> 315 | Y23: =X23 -> 315 | Z23: =Y23 -> 315 | AA23: =Z23 -> 315 | AB23: =AA23 -> 315 | ... AE23: =AD23 -> 315 | AF23: =AE23*(1+Assumptions!$B$23) -> 330.75 | AG23: =AF23 -> 330.75 | AH23: =AG23 -> 330.75 | AI23: =AH23 -> 330.75 | AJ23: =AI23 -> 330.75 | AK23: =AJ23 -> 330.75 | AL23: =AK23 -> 330.75 | AM23: =AL23 -> 330.75 | AN23: =AM23 -> 330.75
A24: Non-Alcoholic Bevarages | H24: =Assumptions!B21 -> 200 | I24: =H24 -> 200 | J24: =I24 -> 200 | K24: =J24 -> 200 | L24: =K24 -> 200 | M24: =L24 -> 200 | N24: =M24 -> 200 | O24: =N24 -> 200 | P24: =O24 -> 200 | ... S24: =R24 -> 200 | T24: =S24*(1+Assumptions!$B$23) -> 210 | U24: =T24 -> 210 | V24: =U24 -> 210 | W24: =V24 -> 210 | X24: =W24 -> 210 | Y24: =X24 -> 210 | Z24: =Y24 -> 210 | AA24: =Z24 -> 210 | AB24: =AA24 -> 210 | ... AE24: =AD24 -> 210 | AF24: =AE24*(1+Assumptions!$B$23) -> 220.5 | AG24: =AF24 -> 220.5 | AH24: =AG24 -> 220.5 | AI24: =AH24 -> 220.5 | AJ24: =AI24 -> 220.5 | AK24: =AJ24 -> 220.5 | AL24: =AK24 -> 220.5 | AM24: =AL24 -> 220.5 | AN24: =AM24 -> 220.5
A25: Food | H25: =Assumptions!B22 -> 1000 | I25: =H25 -> 1000 | J25: =I25 -> 1000 | K25: =J25 -> 1000 | L25: =K25 -> 1000 | M25: =L25 -> 1000 | N25: =M25 -> 1000 | O25: =N25 -> 1000 | P25: =O25 -> 1000 | ... S25: =R25 -> 1000 | T25: =S25*(1+Assumptions!$B$23) -> 1050 | U25: =T25 -> 1050 | V25: =U25 -> 1050 | W25: =V25 -> 1050 | X25: =W25 -> 1050 | Y25: =X25 -> 1050 | Z25: =Y25 -> 1050 | AA25: =Z25 -> 1050 | AB25: =AA25 -> 1050 | ... AE25: =AD25 -> 1050 | AF25: =AE25*(1+Assumptions!$B$23) -> 1102.5 | AG25: =AF25 -> 1102.5 | AH25: =AG25 -> 1102.5 | AI25: =AH25 -> 1102.5 | AJ25: =AI25 -> 1102.5 | AK25: =AJ25 -> 1102.5 | AL25: =AK25 -> 1102.5 | AM25: =AL25 -> 1102.5 | AN25: =AM25 -> 1102.5
A26: Total | H26: =SUM(H23:H25) -> 1500 | I26: =SUM(I23:I25) -> 1500 | J26: =SUM(J23:J25) -> 1500 | K26: =SUM(K23:K25) -> 1500 | L26: =SUM(L23:L25) -> 1500 | M26: =SUM(M23:M25) -> 1500 | N26: =SUM(N23:N25) -> 1500 | O26: =SUM(O23:O25) -> 1500 | ... AN26: =SUM(AN23:AN25) -> 1653.75
A27: Dinner
A28: Alcoholic Beverages | H28: =Assumptions!F20 -> 400 | I28: =H28 -> 400 | J28: =I28 -> 400 | K28: =J28 -> 400 | L28: =K28 -> 400 | M28: =L28 -> 400 | N28: =M28 -> 400 | O28: =N28 -> 400 | P28: =O28 -> 400 | ... S28: =R28 -> 400 | T28: =S28*(1+Assumptions!$F$23) -> 420 | U28: =T28 -> 420 | V28: =U28 -> 420 | W28: =V28 -> 420 | X28: =W28 -> 420 | Y28: =X28 -> 420 | Z28: =Y28 -> 420 | AA28: =Z28 -> 420 | AB28: =AA28 -> 420 | ... AE28: =AD28 -> 420 | AF28: =AE28*(1+Assumptions!$F$23) -> 441 | AG28: =AF28 -> 441 | AH28: =AG28 -> 441 | AI28: =AH28 -> 441 | AJ28: =AI28 -> 441 | AK28: =AJ28 -> 441 | AL28: =AK28 -> 441 | AM28: =AL28 -> 441 | AN28: =AM28 -> 441
A29: Non-Alcoholic Bevarages | H29: =Assumptions!F21 -> 200 | I29: =H29 -> 200 | J29: =I29 -> 200 | K29: =J29 -> 200 | L29: =K29 -> 200 | M29: =L29 -> 200 | N29: =M29 -> 200 | O29: =N29 -> 200 | P29: =O29 -> 200 | ... S29: =R29 -> 200 | T29: =S29*(1+Assumptions!$F$23) -> 210 | U29: =T29 -> 210 | V29: =U29 -> 210 | W29: =V29 -> 210 | X29: =W29 -> 210 | Y29: =X29 -> 210 | Z29: =Y29 -> 210 | AA29: =Z29 -> 210 | AB29: =AA29 -> 210 | ... AE29: =AD29 -> 210 | AF29: =AE29*(1+Assumptions!$F$23) -> 220.5 | AG29: =AF29 -> 220.5 | AH29: =AG29 -> 220.5 | AI29: =AH29 -> 220.5 | AJ29: =AI29 -> 220.5 | AK29: =AJ29 -> 220.5 | AL29: =AK29 -> 220.5 | AM29: =AL29 -> 220.5 | AN29: =AM29 -> 220.5
A30: Food | H30: =Assumptions!F22 -> 1000 | I30: =H30 -> 1000 | J30: =I30 -> 1000 | K30: =J30 -> 1000 | L30: =K30 -> 1000 | M30: =L30 -> 1000 | N30: =M30 -> 1000 | O30: =N30 -> 1000 | P30: =O30 -> 1000 | ... S30: =R30 -> 1000 | T30: =S30*(1+Assumptions!$F$23) -> 1050 | U30: =T30 -> 1050 | V30: =U30 -> 1050 | W30: =V30 -> 1050 | X30: =W30 -> 1050 | Y30: =X30 -> 1050 | Z30: =Y30 -> 1050 | AA30: =Z30 -> 1050 | AB30: =AA30 -> 1050 | ... AE30: =AD30 -> 1050 | AF30: =AE30*(1+Assumptions!$F$23) -> 1102.5 | AG30: =AF30 -> 1102.5 | AH30: =AG30 -> 1102.5 | AI30: =AH30 -> 1102.5 | AJ30: =AI30 -> 1102.5 | AK30: =AJ30 -> 1102.5 | AL30: =AK30 -> 1102.5 | AM30: =AL30 -> 1102.5 | AN30: =AM30 -> 1102.5
A31: Total | H31: =SUM(H28:H30) -> 1600 | I31: =SUM(I28:I30) -> 1600 | J31: =SUM(J28:J30) -> 1600 | K31: =SUM(K28:K30) -> 1600 | L31: =SUM(L28:L30) -> 1600 | M31: =SUM(M28:M30) -> 1600 | N31: =SUM(N28:N30) -> 1600 | O31: =SUM(O28:O30) -> 1600 | ... AN31: =SUM(AN28:AN30) -> 1764
A32: Weekends
A33: Lunch
A34: Alcoholic Beverages | H34: =Assumptions!C20 -> 500 | I34: =H34 -> 500 | J34: =I34 -> 500 | K34: =J34 -> 500 | L34: =K34 -> 500 | M34: =L34 -> 500 | N34: =M34 -> 500 | O34: =N34 -> 500 | P34: =O34 -> 500 | ... S34: =R34 -> 500 | T34: =S34*(1+Assumptions!$C$23) -> 525 | U34: =T34 -> 525 | V34: =U34 -> 525 | W34: =V34 -> 525 | X34: =W34 -> 525 | Y34: =X34 -> 525 | Z34: =Y34 -> 525 | AA34: =Z34 -> 525 | AB34: =AA34 -> 525 | ... AE34: =AD34 -> 525 | AF34: =AE34*(1+Assumptions!$C$23) -> 551.25 | AG34: =AF34 -> 551.25 | AH34: =AG34 -> 551.25 | AI34: =AH34 -> 551.25 | AJ34: =AI34 -> 551.25 | AK34: =AJ34 -> 551.25 | AL34: =AK34 -> 551.25 | AM34: =AL34 -> 551.25 | AN34: =AM34 -> 551.25
A35: Non-Alcoholic Bevarages | H35: =Assumptions!C21 -> 200 | I35: =H35 -> 200 | J35: =I35 -> 200 | K35: =J35 -> 200 | L35: =K35 -> 200 | M35: =L35 -> 200 | N35: =M35 -> 200 | O35: =N35 -> 200 | P35: =O35 -> 200 | ... S35: =R35 -> 200 | T35: =S35*(1+Assumptions!$C$23) -> 210 | U35: =T35 -> 210 | V35: =U35 -> 210 | W35: =V35 -> 210 | X35: =W35 -> 210 | Y35: =X35 -> 210 | Z35: =Y35 -> 210 | AA35: =Z35 -> 210 | AB35: =AA35 -> 210 | ... AE35: =AD35 -> 210 | AF35: =AE35*(1+Assumptions!$C$23) -> 220.5 | AG35: =AF35 -> 220.5 | AH35: =AG35 -> 220.5 | AI35: =AH35 -> 220.5 | AJ35: =AI35 -> 220.5 | AK35: =AJ35 -> 220.5 | AL35: =AK35 -> 220.5 | AM35: =AL35 -> 220.5 | AN35: =AM35 -> 220.5
A36: Food | H36: =Assumptions!C22 -> 1000 | I36: =H36 -> 1000 | J36: =I36 -> 1000 | K36: =J36 -> 1000 | L36: =K36 -> 1000 | M36: =L36 -> 1000 | N36: =M36 -> 1000 | O36: =N36 -> 1000 | P36: =O36 -> 1000 | ... S36: =R36 -> 1000 | T36: =S36*(1+Assumptions!$C$23) -> 1050 | U36: =T36 -> 1050 | V36: =U36 -> 1050 | W36: =V36 -> 1050 | X36: =W36 -> 1050 | Y36: =X36 -> 1050 | Z36: =Y36 -> 1050 | AA36: =Z36 -> 1050 | AB36: =AA36 -> 1050 | ... AE36: =AD36 -> 1050 | AF36: =AE36*(1+Assumptions!$C$23) -> 1102.5 | AG36: =AF36 -> 1102.5 | AH36: =AG36 -> 1102.5 | AI36: =AH36 -> 1102.5 | AJ36: =AI36 -> 1102.5 | AK36: =AJ36 -> 1102.5 | AL36: =AK36 -> 1102.5 | AM36: =AL36 -> 1102.5 | AN36: =AM36 -> 1102.5
A37: Total | H37: =SUM(H34:H36) -> 1700 | I37: =SUM(I34:I36) -> 1700 | J37: =SUM(J34:J36) -> 1700 | K37: =SUM(K34:K36) -> 1700 | L37: =SUM(L34:L36) -> 1700 | M37: =SUM(M34:M36) -> 1700 | N37: =SUM(N34:N36) -> 1700 | O37: =SUM(O34:O36) -> 1700 | ... AN37: =SUM(AN34:AN36) -> 1874.25
A38: Dinner
A39: Alcoholic Beverages | H39: =Assumptions!G20 -> 650 | I39: =H39 -> 650 | J39: =I39 -> 650 | K39: =J39 -> 650 | L39: =K39 -> 650 | M39: =L39 -> 650 | N39: =M39 -> 650 | O39: =N39 -> 650 | P39: =O39 -> 650 | ... S39: =R39 -> 650 | T39: =S39*(1+Assumptions!$G$23) -> 682.5 | U39: =T39 -> 682.5 | V39: =U39 -> 682.5 | W39: =V39 -> 682.5 | X39: =W39 -> 682.5 | Y39: =X39 -> 682.5 | Z39: =Y39 -> 682.5 | AA39: =Z39 -> 682.5 | AB39: =AA39 -> 682.5 | ... AE39: =AD39 -> 682.5 | AF39: =AE39*(1+Assumptions!$G$23) -> 716.625 | AG39: =AF39 -> 716.625 | AH39: =AG39 -> 716.625 | AI39: =AH39 -> 716.625 | AJ39: =AI39 -> 716.625 | AK39: =AJ39 -> 716.625 | AL39: =AK39 -> 716.625 | AM39: =AL39 -> 716.625 | AN39: =AM39 -> 716.625
A40: Non-Alcoholic Bevarages | H40: =Assumptions!G21 -> 250 | I40: =H40 -> 250 | J40: =I40 -> 250 | K40: =J40 -> 250 | L40: =K40 -> 250 | M40: =L40 -> 250 | N40: =M40 -> 250 | O40: =N40 -> 250 | P40: =O40 -> 250 | ... S40: =R40 -> 250 | T40: =S40*(1+Assumptions!$G$23) -> 262.5 | U40: =T40 -> 262.5 | V40: =U40 -> 262.5 | W40: =V40 -> 262.5 | X40: =W40 -> 262.5 | Y40: =X40 -> 262.5 | Z40: =Y40 -> 262.5 | AA40: =Z40 -> 262.5 | AB40: =AA40 -> 262.5 | ... AE40: =AD40 -> 262.5 | AF40: =AE40*(1+Assumptions!$G$23) -> 275.625 | AG40: =AF40 -> 275.625 | AH40: =AG40 -> 275.625 | AI40: =AH40 -> 275.625 | AJ40: =AI40 -> 275.625 | AK40: =AJ40 -> 275.625 | AL40: =AK40 -> 275.625 | AM40: =AL40 -> 275.625 | AN40: =AM40 -> 275.625
A41: Food | H41: =Assumptions!G22 -> 1000 | I41: =H41 -> 1000 | J41: =I41 -> 1000 | K41: =J41 -> 1000 | L41: =K41 -> 1000 | M41: =L41 -> 1000 | N41: =M41 -> 1000 | O41: =N41 -> 1000 | P41: =O41 -> 1000 | ... S41: =R41 -> 1000 | T41: =S41*(1+Assumptions!$G$23) -> 1050 | U41: =T41 -> 1050 | V41: =U41 -> 1050 | W41: =V41 -> 1050 | X41: =W41 -> 1050 | Y41: =X41 -> 1050 | Z41: =Y41 -> 1050 | AA41: =Z41 -> 1050 | AB41: =AA41 -> 1050 | ... AE41: =AD41 -> 1050 | AF41: =AE41*(1+Assumptions!$G$23) -> 1102.5 | AG41: =AF41 -> 1102.5 | AH41: =AG41 -> 1102.5 | AI41: =AH41 -> 1102.5 | AJ41: =AI41 -> 1102.5 | AK41: =AJ41 -> 1102.5 | AL41: =AK41 -> 1102.5 | AM41: =AL41 -> 1102.5 | AN41: =AM41 -> 1102.5
A42: Total | H42: =SUM(H39:H41) -> 1900 | I42: =SUM(I39:I41) -> 1900 | J42: =SUM(J39:J41) -> 1900 | K42: =SUM(K39:K41) -> 1900 | L42: =SUM(L39:L41) -> 1900 | M42: =SUM(M39:M41) -> 1900 | N42: =SUM(N39:N41) -> 1900 | O42: =SUM(O39:O41) -> 1900 | ... AN42: =SUM(AN39:AN41) -> 2094.75
A44: Revenue Per Month
A45: Weekdays
A46: Lunch
...

Sheet Monthly P&L
H2: Monthly P&L
A4: All Values in: | B4: KSh
E5: 1 | F5: =E5+1 -> 2 | G5: =F5+1 -> 3 | H5: =G5+1 -> 4 | I5: =H5+1 -> 5 | J5: =I5+1 -> 6 | K5: =J5+1 -> 7 | L5: =K5+1 -> 8 | M5: =L5+1 -> 9 | ... AN5: =AM5+1 -> 36
E6: =EOMONTH(Assumptions!C5,0) -> 43951 | F6: =EOMONTH(E6,1) -> 43982 | G6: =EOMONTH(F6,1) -> 44012 | H6: =EOMONTH(G6,1) -> 44043 | I6: =EOMONTH(H6,1) -> 44074 | J6: =EOMONTH(I6,1) -> 44104 | K6: =EOMONTH(J6,1) -> 44135 | L6: =EOMONTH(K6,1) -> 44165 | M6: =EOMONTH(L6,1) -> 44196 | ... AN6: =EOMONTH(AM6,1) -> 45016
A8: Revenue
A9: ='Monthly Revenue'!A70 -> Alcoholic Beverages | E9: ='Monthly Revenue'!E70 -> 0 | F9: ='Monthly Revenue'!F70 -> 0 | G9: ='Monthly Revenue'!G70 -> 0 | H9: ='Monthly Revenue'!H70 -> 637200 | I9: ='Monthly Revenue'!I70 -> 689288 | J9: ='Monthly Revenue'!J70 -> 656592.32 | K9: ='Monthly Revenue'!K70 -> 711906.57 | L9: ='Monthly Revenue'!L70 -> 714973.26 | ... AN9: ='Monthly Revenue'!AN70 -> 1652480.7
A10: ='Monthly Revenue'!A71 -> Non-Alcoholic Bevarages | E10: ='Monthly Revenue'!E71 -> 0 | F10: ='Monthly Revenue'!F71 -> 0 | G10: ='Monthly Revenue'!G71 -> 0 | H10: ='Monthly Revenue'!H71 -> 313200 | I10: ='Monthly Revenue'!I71 -> 329144 | J10: ='Monthly Revenue'!J71 -> 320467.52 | K10: ='Monthly Revenue'!K71 -> 343360.45 | L10: ='Monthly Revenue'!L71 -> 342840.73 | ... AN10: ='Monthly Revenue'!AN71 -> 779212.59
A11: ='Monthly Revenue'!A72 -> Food | E11: ='Monthly Revenue'!E72 -> 0 | F11: ='Monthly Revenue'!F72 -> 0 | G11: ='Monthly Revenue'!G72 -> 0 | H11: ='Monthly Revenue'!H72 -> 1506000 | I11: ='Monthly Revenue'!I72 -> 1567720 | J11: ='Monthly Revenue'!J72 -> 1537441.6 | K11: ='Monthly Revenue'!K72 -> 1640874 | L11: ='Monthly Revenue'!L72 -> 1635238.2 | ... AN11: ='Monthly Revenue'!AN72 -> 3697613
A12: ='Monthly Revenue'!A73 -> Total Monthly Revenue | E12: ='Monthly Revenue'!E73 -> 0 | F12: ='Monthly Revenue'!F73 -> 0 | G12: ='Monthly Revenue'!G73 -> 0 | H12: ='Monthly Revenue'!H73 -> 2456400 | I12: ='Monthly Revenue'!I73 -> 2586152 | J12: ='Monthly Revenue'!J73 -> 2514501.4 | K12: ='Monthly Revenue'!K73 -> 2696141 | L12: ='Monthly Revenue'!L73 -> 2693052.2 | ... AN12: ='Monthly Revenue'!AN73 -> 6129306.2
A14: Less: Direct Expenses
A15: =Assumptions!A34 -> Alcoholic Beverage Cost (% of Revenue | H15: =Assumptions!$D34*'Monthly P&L'!H9 -> 223020 | I15: =Assumptions!$D34*'Monthly P&L'!I9 -> 241250.8 | J15: =Assumptions!$D34*'Monthly P&L'!J9 -> 229807.31 | K15: =Assumptions!$D34*'Monthly P&L'!K9 -> 249167.3 | L15: =Assumptions!$D34*'Monthly P&L'!L9 -> 250240.64 | M15: =Assumptions!$D34*'Monthly P&L'!M9 -> 256476.16 | N15: =Assumptions!$D34*'Monthly P&L'!N9 -> 279677.66 | O15: =Assumptions!$D34*'Monthly P&L'!O9 -> 251618.91 | ... AN15: =Assumptions!$D34*'Monthly P&L'!AN9 -> 578368.25
A16: =Assumptions!A35 -> Non Alcoholic Beverage Cost (% of Revenue) | H16: =Assumptions!$D35*'Monthly P&L'!H10 -> 125280 | I16: =Assumptions!$D35*'Monthly P&L'!I10 -> 131657.6 | J16: =Assumptions!$D35*'Monthly P&L'!J10 -> 128187.01 | K16: =Assumptions!$D35*'Monthly P&L'!K10 -> 137344.18 | L16: =Assumptions!$D35*'Monthly P&L'!L10 -> 137136.29 | M16: =Assumptions!$D35*'Monthly P&L'!M10 -> 142894.17 | N16: =Assumptions!$D35*'Monthly P&L'!N10 -> 151308.04 | O16: =Assumptions!$D35*'Monthly P&L'!O10 -> 138022.73 | ... AN16: =Assumptions!$D35*'Monthly P&L'!AN10 -> 311685.04
A17: =Assumptions!A36 -> Food Cost (% of Revenue) | H17: =Assumptions!$D36*'Monthly P&L'!H11 -> 451800 | I17: =Assumptions!$D36*'Monthly P&L'!I11 -> 470316 | J17: =Assumptions!$D36*'Monthly P&L'!J11 -> 461232.48 | K17: =Assumptions!$D36*'Monthly P&L'!K11 -> 492262.19 | L17: =Assumptions!$D36*'Monthly P&L'!L11 -> 490571.45 | M17: =Assumptions!$D36*'Monthly P&L'!M11 -> 513953.4 | N17: =Assumptions!$D36*'Monthly P&L'!N11 -> 538935.46 | O17: =Assumptions!$D36*'Monthly P&L'!O11 -> 493898.48 | ... AN17: =Assumptions!$D36*'Monthly P&L'!AN11 -> 1109283.9
A18: Staff Salary | H18: =Assumptions!D50 -> 986000 | I18: =H18 -> 986000 | J18: =I18 -> 986000 | K18: =J18 -> 986000 | L18: =K18 -> 986000 | M18: =L18 -> 986000 | N18: =M18 -> 986000 | O18: =N18 -> 986000 | P18: =O18 -> 986000 | ... S18: =R18 -> 986000 | T18: =S18*(1+Assumptions!$B$52) -> 1104320 | U18: =T18 -> 1104320 | V18: =U18 -> 1104320 | W18: =V18 -> 1104320 | X18: =W18 -> 1104320 | Y18: =X18 -> 1104320 | Z18: =Y18 -> 1104320 | AA18: =Z18 -> 1104320 | AB18: =AA18 -> 1104320 | ... AE18: =AD18 -> 1104320 | AF18: =AE18*(1+Assumptions!$B$52) -> 1236838.4 | AG18: =AF18 -> 1236838.4 | AH18: =AG18 -> 1236838.4 | AI18: =AH18 -> 1236838.4 | AJ18: =AI18 -> 1236838.4 | AK18: =AJ18 -> 1236838.4 | AL18: =AK18 -> 1236838.4 | AM18: =AL18 -> 1236838.4 | AN18: =AM18 -> 1236838.4
A19: Total Direct Expenses | H19: =SUM(H15:H18) -> 1786100 | I19: =SUM(I15:I18) -> 1829224.4 | J19: =SUM(J15:J18) -> 1805226.8 | K19: =SUM(K15:K18) -> 1864773.7 | L19: =SUM(L15:L18) -> 1863948.4 | M19: =SUM(M15:M18) -> 1899323.7 | N19: =SUM(N15:N18) -> 1955921.2 | O19: =SUM(O15:O18) -> 1869540.1 | ... AN19: =SUM(AN15:AN18) -> 3236175.6
A21: Less: Indirect Expenses
A22: Other Staff Salary | H22: =Assumptions!D63 -> 380000 | I22: =H22 -> 380000 | J22: =I22 -> 380000 | K22: =J22 -> 380000 | L22: =K22 -> 380000 | M22: =L22 -> 380000 | N22: =M22 -> 380000 | O22: =N22 -> 380000 | P22: =O22 -> 380000 | ... S22: =R22 -> 380000 | T22: =S22*(1+Assumptions!$C$76) -> 437000 | U22: =T22 -> 437000 | V22: =U22 -> 437000 | W22: =V22 -> 437000 | X22: =W22 -> 437000 | Y22: =X22 -> 437000 | Z22: =Y22 -> 437000 | AA22: =Z22 -> 437000 | AB22: =AA22 -> 437000 | ... AE22: =AD22 -> 437000 | AF22: =AE22*(1+Assumptions!$C$76) -> 502550 | AG22: =AF22 -> 502550 | AH22: =AG22 -> 502550 | AI22: =AH22 -> 502550 | AJ22: =AI22 -> 502550 | AK22: =AJ22 -> 502550 | AL22: =AK22 -> 502550 | AM22: =AL22 -> 502550 | AN22: =AM22 -> 502550
A23: =Assumptions!A65 -> Royalty to Brand (% of Revenue) | H23: =Assumptions!$D$65*'Monthly P&L'!H12 -> 122820 | I23: =Assumptions!$D$65*'Monthly P&L'!I12 -> 129307.6 | J23: =Assumptions!$D$65*'Monthly P&L'!J12 -> 125725.07 | K23: =Assumptions!$D$65*'Monthly P&L'!K12 -> 134807.05 | L23: =Assumptions!$D$65*'Monthly P&L'!L12 -> 134652.61 | M23: =Assumptions!$D$65*'Monthly P&L'!M12 -> 140160.12 | N23: =Assumptions!$D$65*'Monthly P&L'!N12 -> 148690.03 | O23: =Assumptions!$D$65*'Monthly P&L'!O12 -> 135514.81 | ... AN23: =Assumptions!$D$65*'Monthly P&L'!AN12 -> 306465.31
A24: =Assumptions!A66 -> Rent (% of Revenue) | H24: =Assumptions!$D$66*'Monthly P&L'!H12 -> 245640 | I24: =Assumptions!$D$66*'Monthly P&L'!I12 -> 258615.2 | J24: =Assumptions!$D$66*'Monthly P&L'!J12 -> 251450.14 | K24: =Assumptions!$D$66*'Monthly P&L'!K12 -> 269614.1 | L24: =Assumptions!$D$66*'Monthly P&L'!L12 -> 269305.22 | M24: =Assumptions!$D$66*'Monthly P&L'!M12 -> 280320.25 | N24: =Assumptions!$D$66*'Monthly P&L'!N12 -> 297380.07 | O24: =Assumptions!$D$66*'Monthly P&L'!O12 -> 271029.62 | ... AN24: =Assumptions!$D$66*'Monthly P&L'!AN12 -> 612930.62
A25: =Assumptions!A67 -> Water Cost/M | H25: =Assumptions!D67 -> 10000 | I25: =H25 -> 10000 | J25: =I25 -> 10000 | K25: =J25 -> 10000 | L25: =K25 -> 10000 | M25: =L25 -> 10000 | N25: =M25 -> 10000 | O25: =N25 -> 10000 | P25: =O25 -> 10000 | ... S25: =R25 -> 10000 | T25: =S25*(1+Assumptions!$C$76) -> 11500 | U25: =T25 -> 11500 | V25: =U25 -> 11500 | W25: =V25 -> 11500 | X25: =W25 -> 11500 | Y25: =X25 -> 11500 | Z25: =Y25 -> 11500 | AA25: =Z25 -> 11500 | AB25: =AA25 -> 11500 | ... AE25: =AD25 -> 11500 | AF25: =AE25*(1+Assumptions!$C$76) -> 13225 | AG25: =AF25 -> 13225 | AH25: =AG25 -> 13225 | AI25: =AH25 -> 13225 | AJ25: =AI25 -> 13225 | AK25: =AJ25 -> 13225 | AL25: =AK25 -> 13225 | AM25: =AL25 -> 13225 | AN25: =AM25 -> 13225
A26: =Assumptions!A68 -> Maintenance/M | H26: =Assumptions!D68 -> 50000 | I26: =H26 -> 50000 | J26: =I26 -> 50000 | K26: =J26 -> 50000 | L26: =K26 -> 50000 | M26: =L26 -> 50000 | N26: =M26 -> 50000 | O26: =N26 -> 50000 | P26: =O26 -> 50000 | ... S26: =R26 -> 50000 | T26: =S26*(1+Assumptions!$C$76) -> 57500 | U26: =T26 -> 57500 | V26: =U26 -> 57500 | W26: =V26 -> 57500 | X26: =W26 -> 57500 | Y26: =X26 -> 57500 | Z26: =Y26 -> 57500 | AA26: =Z26 -> 57500 | AB26: =AA26 -> 57500 | ... AE26: =AD26 -> 57500 | AF26: =AE26*(1+Assumptions!$C$76) -> 66125 | AG26: =AF26 -> 66125 | AH26: =AG26 -> 66125 | AI26: =AH26 -> 66125 | AJ26: =AI26 -> 66125 | AK26: =AJ26 -> 66125 | AL26: =AK26 -> 66125 | AM26: =AL26 -> 66125 | AN26: =AM26 -> 66125
A27: =Assumptions!A69 -> Marketing Cost/M | H27: =Assumptions!D69 -> 25000 | I27: =H27 -> 25000 | J27: =I27 -> 25000 | K27: =J27 -> 25000 | L27: =K27 -> 25000 | M27: =L27 -> 25000 | N27: =M27 -> 25000 | O27: =N27 -> 25000 | P27: =O27 -> 25000 | ... S27: =R27 -> 25000 | T27: =S27*(1+Assumptions!$C$76) -> 28750 | U27: =T27 -> 28750 | V27: =U27 -> 28750 | W27: =V27 -> 28750 | X27: =W27 -> 28750 | Y27: =X27 -> 28750 | Z27: =Y27 -> 28750 | AA27: =Z27 -> 28750 | AB27: =AA27 -> 28750 | ... AE27: =AD27 -> 28750 | AF27: =AE27*(1+Assumptions!$C$76) -> 33062.5 | AG27: =AF27 -> 33062.5 | AH27: =AG27 -> 33062.5 | AI27: =AH27 -> 33062.5 | AJ27: =AI27 -> 33062.5 | AK27: =AJ27 -> 33062.5 | AL27: =AK27 -> 33062.5 | AM27: =AL27 -> 33062.5 | AN27: =AM27 -> 33062.5
A28: =Assumptions!A70 -> Electricity (Based on Area $/sq. Ft) | H28: =Assumptions!$D$70*Assumptions!$C$82 -> 26600 | I28: =Assumptions!$D$70*Assumptions!$C$82 -> 26600 | J28: =Assumptions!$D$70*Assumptions!$C$82 -> 26600 | K28: =Assumptions!$D$70*Assumptions!$C$82 -> 26600 | L28: =Assumptions!$D$70*Assumptions!$C$82 -> 26600 | M28: =Assumptions!$D$70*Assumptions!$C$82 -> 26600 | N28: =Assumptions!$D$70*Assumptions!$C$82 -> 26600 | O28: =Assumptions!$D$70*Assumptions!$C$82 -> 26600 | ... S28: =Assumptions!$D$70*Assumptions!$C$82 -> 26600 | T28: =S28*(1+Assumptions!C76) -> 30590 | U28: =T28 -> 30590 | V28: =U28 -> 30590 | W28: =V28 -> 30590 | X28: =W28 -> 30590 | Y28: =X28 -> 30590 | Z28: =Y28 -> 30590 | AA28: =Z28 -> 30590 | AB28: =AA28 -> 30590 | ... AE28: =AD28 -> 30590 | AF28: =AE28*(1+Assumptions!C76) -> 35178.5 | AG28: =AF28 -> 35178.5 | AH28: =AG28 -> 35178.5 | AI28: =AH28 -> 35178.5 | AJ28: =AI28 -> 35178.5 | AK28: =AJ28 -> 35178.5 | AL28: =AK28 -> 35178.5 | AM28: =AL28 -> 35178.5 | AN28: =AM28 -> 35178.5
A29: =Assumptions!A71 -> Phone & Internet/M | H29: =Assumptions!D71 -> 15000 | I29: =H29 -> 15000 | J29: =I29 -> 15000 | K29: =J29 -> 15000 | L29: =K29 -> 15000 | M29: =L29 -> 15000 | N29: =M29 -> 15000 | O29: =N29 -> 15000 | P29: =O29 -> 15000 | ... S29: =R29 -> 15000 | T29: =S29*(1+Assumptions!C76) -> 17250 | U29: =T29 -> 17250 | V29: =U29 -> 17250 | W29: =V29 -> 17250 | X29: =W29 -> 17250 | Y29: =X29 -> 17250 | Z29: =Y29 -> 17250 | AA29: =Z29 -> 17250 | AB29: =AA29 -> 17250 | ... AE29: =AD29 -> 17250 | AF29: =AE29*(1+Assumptions!C76) -> 19837.5 | AG29: =AF29 -> 19837.5 | AH29: =AG29 -> 19837.5 | AI29: =AH29 -> 19837.5 | AJ29: =AI29 -> 19837.5 | AK29: =AJ29 -> 19837.5 | AL29: =AK29 -> 19837.5 | AM29: =AL29 -> 19837.5 | AN29: =AM29 -> 19837.5
A30: =Assumptions!A72 -> Housekeeping & Consumables (% of Revenue) | H30: =Assumptions!$D$72*'Monthly P&L'!H12 -> 49128 | I30: =Assumptions!$D$72*'Monthly P&L'!I12 -> 51723.04 | J30: =Assumptions!$D$72*'Monthly P&L'!J12 -> 50290.029 | K30: =Assumptions!$D$72*'Monthly P&L'!K12 -> 53922.819 | L30: =Assumptions!$D$72*'Monthly P&L'!L12 -> 53861.043 | M30: =Assumptions!$D$72*'Monthly P&L'!M12 -> 56064.049 | N30: =Assumptions!$D$72*'Monthly P&L'!N12 -> 59476.013 | O30: =Assumptions!$D$72*'Monthly P&L'!O12 -> 54205.925 | ... AN30: =Assumptions!$D$72*'Monthly P&L'!AN12 -> 122586.12
A31: =Assumptions!A73 -> Payment Settlement Charges (% of Revenue) | H31: =Assumptions!$D$73*'Monthly P&L'!H12*Assumptions!$D$74 -> 18423 | I31: =Assumptions!$D$73*'Monthly P&L'!I12*Assumptions!$D$74 -> 19396.14 | J31: =Assumptions!$D$73*'Monthly P&L'!J12*Assumptions!$D$74 -> 18858.761 | K31: =Assumptions!$D$73*'Monthly P&L'!K12*Assumptions!$D$74 -> 20221.057 | L31: =Assumptions!$D$73*'Monthly P&L'!L12*Assumptions!$D$74 -> 20197.891 | M31: =Assumptions!$D$73*'Monthly P&L'!M12*Assumptions!$D$74 -> 21024.018 | N31: =Assumptions!$D$73*'Monthly P&L'!N12*Assumptions!$D$74 -> 22303.505 | O31: =Assumptions!$D$73*'Monthly P&L'!O12*Assumptions!$D$74 -> 20327.222 | ... AN31: =Assumptions!$D$73*'Monthly P&L'!AN12*Assumptions!$D$74 -> 45969.797
A32: Total Indirect Expenses | H32: =SUM(H22:H31) -> 942611 | I32: =SUM(I22:I31) -> 965641.98 | J32: =SUM(J22:J31) -> 952924.01 | K32: =SUM(K22:K31) -> 985165.02 | L32: =SUM(L22:L31) -> 984616.76 | M32: =SUM(M22:M31) -> 1004168.4 | N32: =SUM(N22:N31) -> 1034449.6 | O32: =SUM(O22:O31) -> 987677.58 | ... AN32: =SUM(AN22:AN31) -> 1757930.4
A34: EBITDA | H34: =H12-H19-H32 -> -272311 | I34: =I12-I19-I32 -> -208714.38 | J34: =J12-J19-J32 -> -243649.37 | K34: =K12-K19-K32 -> -153797.72 | L34: =L12-L19-L32 -> -155512.98 | M34: =M12-M19-M32 -> -100289.71 | N34: =N12-N19-N32 -> -16570.115 | O34: =O12-O19-O32 -> -146921.45 | ... AN34: =AN12-AN19-AN32 -> 1135200.3
A36: EBITDA Margin | H36: =H34/H12 -> -0.11085776 | I36: =I34/I12 -> -0.080704607 | J36: =J34/J12 -> -0.096897684 | K36: =K34/K12 -> -0.057043648 | L36: =L34/L12 -> -0.057745994 | M36: =M34/M12 -> -0.035776835 | N36: =N34/N12 -> -0.005572033 | O36: =O34/O12 -> -0.054208633 | ... AN36: =AN34/AN12 -> 0.18520861
A39: End of Sheet

Sheet Capital Structure
D2: The Business Capital Structure
A4: All Values in: | B4: KSh
D5: Month 0
D6: =Assumptions!C5 -> 43951
A8: Fixed Assets
A9: =Assumptions!A94 -> Kitchen Eq. & Cutlery | D9: =Assumptions!$B$94*Assumptions!$C$85 -> 3000000
A10: =Assumptions!A95 -> Refrigeration | D10: =Assumptions!$B$95*Assumptions!$C$85 -> 5000000
A11: =Assumptions!A96 -> Furniture | D11: =Assumptions!$B$96*Assumptions!$C$84 -> 5100000
A12: =Assumptions!A97 -> Restaurants Décor | D12: =Assumptions!$B$97*Assumptions!$C$84 -> 6000000
A13: Total Fixed Assets | D13: =SUM(D9:D12) -> 19100000
A14: Add:
A15: Rent Deposit | D15: =Assumptions!B98 -> 1000000
A16: Initial Working Capital | D16: =Assumptions!B102 -> 2400000
A18: Total Funds Required | D18: =SUM(D13,D15,D16) -> 22500000
A20: Sources of Capital
A21: Equity | C21: =Assumptions!B117 -> 1 | D21: =C21*D18 -> 22500000
A22: Debt | C22: =Assumptions!B118 -> 0 | D22: =C22*D18 -> 0
A23: Total Funds Contributed | D23: =SUM(D21:D22) -> 22500000
A26: End of Sheet

Sheet Fixed Assets Schedule
D1: Fixed Assets Schedule
A4: All Values in: | B4: KSh
D5: Construction End Date | E5: 1 | F5: 2 | G5: 3
D6: =Assumptions!G14 -> 44013 | E6: =EOMONTH(Assumptions!C5,11) -> 44286 | F6: =EOMONTH(E6,12) -> 44651 | G6: =EOMONTH(F6,12) -> 45016
A8: ='Capital Structure'!A9 -> Kitchen Eq. & Cutlery
A9: Opening Bal | E9: 0 | F9: =E13 -> 2663424.7 | G9: =F13 -> 2263911
A10: Add: Purchases | E10: ='Capital Structure'!D9 -> 3000000 | F10: 0 | G10: 0
A11: Less: Sales | E11: 0 | F11: 0 | G11: 0
A12: Less: Depreciation | E12: =(E9+E10-E11)*Assumptions!$C$112*DATEDIF('Fixed Assets Schedule'!D$6,'Fixed Assets Schedule'!E$6,"d")/365 -> 336575.34 | F12: =(F9+F10-F11)*Assumptions!$C$112*DATEDIF('Fixed Assets Schedule'!E$6,'Fixed Assets Schedule'!F$6,"d")/365 -> 399513.7 | G12: =(G9+G10-G11)*Assumptions!$C$112*DATEDIF('Fixed Assets Schedule'!F$6,'Fixed Assets Schedule'!G$6,"d")/365 -> 339586.64
A13: Closing Bal | E13: =E9+E10-E11-E12 -> 2663424.7 | F13: =F9+F10-F11-F12 -> 2263911 | G13: =G9+G10-G11-G12 -> 1924324.3
A15: ='Capital Structure'!A10 -> Refrigeration
A16: Opening Bal | E16: 0 | F16: =E20 -> 4439041.1 | G16: =F20 -> 3773184.9
A17: Add: Purchases | E17: ='Capital Structure'!D10 -> 5000000
A18: Less: Sales | E18: 0 | F18: 0 | G18: 0
A19: Less: Depreciation | E19: =(E16+E17-E18)*Assumptions!$C$112*DATEDIF('Fixed Assets Schedule'!D$6,'Fixed Assets Schedule'!E$6,"d")/365 -> 560958.9 | F19: =(F16+F17-F18)*Assumptions!$C$112*DATEDIF('Fixed Assets Schedule'!E$6,'Fixed Assets Schedule'!F$6,"d")/365 -> 665856.16 | G19: =(G16+G17-G18)*Assumptions!$C$112*DATEDIF('Fixed Assets Schedule'!F$6,'Fixed Assets Schedule'!G$6,"d")/365 -> 565977.74
A20: Closing Bal | E20: =E16+E17-E18-E19 -> 4439041.1 | F20: =F16+F17-F18-F19 -> 3773184.9 | G20: =G16+G17-G18-G19 -> 3207207.2
A22: ='Capital Structure'!A11 -> Furniture
A23: Opening Bal | E23: 0 | F23: =E27 -> 4718547.9 | G23: =F27 -> 4246693.2
A24: Add: Purchases | E24: ='Capital Structure'!D11 -> 5100000
A25: Less: Sales | E25: 0 | F25: 0 | G25: 0
A26: Less: Depreciation | E26: =(E23+E24-E25)*Assumptions!$C$113*DATEDIF('Fixed Assets Schedule'!D$6,'Fixed Assets Schedule'!E$6,"d")/365 -> 381452.05 | F26: =(F23+F24-F25)*Assumptions!$C$113*DATEDIF('Fixed Assets Schedule'!E$6,'Fixed Assets Schedule'!F$6,"d")/365 -> 471854.79 | G26: =(G23+G24-G25)*Assumptions!$C$113*DATEDIF('Fixed Assets Schedule'!F$6,'Fixed Assets Schedule'!G$6,"d")/365 -> 424669.32
A27: Closing Bal | E27: =E23+E24-E25-E26 -> 4718547.9 | F27: =F23+F24-F25-F26 -> 4246693.2 | G27: =G23+G24-G25-G26 -> 3822023.8
A30: ='Capital Structure'!A12 -> Restaurants Décor
A31: Opening Bal | E31: 0 | F31: =E35 -> 5551232.9 | G31: =F35 -> 4996109.6
A32: Add: Purchases | E32: ='Capital Structure'!D12 -> 6000000
A33: Less: Sales | E33: 0 | F33: 0 | G33: 0
A34: Less: Depreciation | E34: =(E31+E32-E33)*Assumptions!$C$113*DATEDIF('Fixed Assets Schedule'!D$6,'Fixed Assets Schedule'!E$6,"d")/365 -> 448767.12 | F34: =(F31+F32-F33)*Assumptions!$C$113*DATEDIF('Fixed Assets Schedule'!E$6,'Fixed Assets Schedule'!F$6,"d")/365 -> 555123.29 | G34: =(G31+G32-G33)*Assumptions!$C$113*DATEDIF('Fixed Assets Schedule'!F$6,'Fixed Assets Schedule'!G$6,"d")/365 -> 499610.96
A35: Closing Bal | E35: =E31+E32-E33-E34 -> 5551232.9 | F35: =F31+F32-F33-F34 -> 4996109.6 | G35: =G31+G32-G33-G34 -> 4496498.6
A39: End of Sheet

Sheet Working Capital
D1: Working Capital
A4: All Values in: | B4: KSh
E5: 1 | F5: 2 | G5: 3
E6: =EOMONTH(Assumptions!C5,11) -> 44286 | F6: =EOMONTH(E6,12) -> 44651 | G6: =EOMONTH(F6,12) -> 45016
A7: Current Assets
A8: =Assumptions!A104 -> Alcoholic Beverages | E8: ='Monthly P&L'!P15/30*Assumptions!$B104 -> 279222.26 | F8: ='Monthly P&L'!AB15/30*Assumptions!$B104 -> 415345.33 | G8: ='Monthly P&L'!AN15/30*Assumptions!$B104 -> 578368.25
A9: =Assumptions!A105 -> Non-Alcoholic Beverages | E9: ='Monthly P&L'!P16/30*Assumptions!$B105 -> 77393.948 | F9: ='Monthly P&L'!AB16/30*Assumptions!$B105 -> 112779.36 | G9: ='Monthly P&L'!AN16/30*Assumptions!$B105 -> 155842.52
A10: =Assumptions!A106 -> Food | E10: ='Monthly P&L'!P17/30*Assumptions!$B106 -> 92636.728 | F10: ='Monthly P&L'!AB17/30*Assumptions!$B106 -> 134072.16 | G10: ='Monthly P&L'!AN17/30*Assumptions!$B106 -> 184880.65
A11: Total | E11: =SUM(E8:E10) -> 449252.93 | F11: =SUM(F8:F10) -> 662196.86 | G11: =SUM(G8:G10) -> 919091.41
A14: Current Liabilites
A15: =Assumptions!A107 -> Creditor for R/Mtrls | E15: ='Monthly P&L'!P32/30*Assumptions!B108 -> 1045753.1 | F15: ='Monthly P&L'!AB32/30*Assumptions!B108 -> 1369277.3 | G15: ='Monthly P&L'!AN32/30*Assumptions!B108 -> 1757930.4
A16: Creditor for Expenses:
A17: Alcoholic Beverages | E17: ='Monthly P&L'!P15/30*Assumptions!B$107 -> 279222.26 | F17: ='Monthly P&L'!AB15/30*Assumptions!B$107 -> 415345.33 | G17: ='Monthly P&L'!AN15/30*Assumptions!B$107 -> 578368.25
A18: Non-alcoholic Beverages | E18: ='Monthly P&L'!P16/30*Assumptions!B$107 -> 154787.9 | F18: ='Monthly P&L'!AB16/30*Assumptions!B$107 -> 225558.72 | G18: ='Monthly P&L'!AN16/30*Assumptions!B$107 -> 311685.04
A19: Food | E19: ='Monthly P&L'!P17/30*Assumptions!B$107 -> 555820.37 | F19: ='Monthly P&L'!AB17/30*Assumptions!B$107 -> 804432.99 | G19: ='Monthly P&L'!AN17/30*Assumptions!B$107 -> 1109283.9
A20: Total | E20: =E15+E17+E18+E19 -> 2035583.6 | F20: =F15+F17+F18+F19 -> 2814614.3 | G20: =G15+G17+G18+G19 -> 3757267.5
A23: Working Capital | E23: =E11-E20 -> -1586330.7 | F23: =F11-F20 -> -2152417.5 | G23: =G11-G20 -> -2838176.1
A25: Changes in Working Capital | E25: =-(E23-D23) -> 1586330.7 | F25: =-(F23-E23) -> 566086.8 | G25: =-(G23-F23) -> 685758.65
A28: End of Sheet

Sheet Annual P&L
C2: Annual P&L for the Business
A4: All Values in: | B4: KSh
F5: 1 | G5: 2 | H5: 3
F6: =EOMONTH(Assumptions!C5,11) -> 44286 | G6: =EOMONTH(F6,12) -> 44651 | H6: =EOMONTH(G6,12) -> 45016
A8: Revenue
A9: ='Monthly Revenue'!A70 -> Alcoholic Beverages | F9: =SUM('Monthly P&L'!$H9:$P9) -> 6458517.2 | G9: =SUM('Monthly P&L'!$Q9:$AB9) -> 12187672 | H9: =SUM('Monthly P&L'!$AC9:$AN9) -> 18072179
A10: ='Monthly Revenue'!A71 -> Non-Alcoholic Bevarages | F10: =SUM('Monthly P&L'!$H10:$P10) -> 3116544.8 | G10: =SUM('Monthly P&L'!$Q10:$AB10) -> 5773268.5 | H10: =SUM('Monthly P&L'!$AC10:$AN10) -> 8408599.1
A11: ='Monthly Revenue'!A72 -> Food | F11: =SUM('Monthly P&L'!$H11:$P11) -> 14895966 | G11: =SUM('Monthly P&L'!$Q11:$AB11) -> 27424132 | H11: =SUM('Monthly P&L'!$AC11:$AN11) -> 39706350
A12: ='Monthly Revenue'!A73 -> Total Monthly Revenue | F12: =SUM(F9:F11) -> 24471028 | G12: =SUM(G9:G11) -> 45385072 | H12: =SUM(H9:H11) -> 66187128
A14: Less: Direct Expenses
A15: =Assumptions!A34 -> Alcoholic Beverage Cost (% of Revenue | F15: =SUM('Monthly P&L'!$H15:$P15) -> 2260481 | G15: =SUM('Monthly P&L'!$Q15:$AB15) -> 4265685.1 | H15: =SUM('Monthly P&L'!$AC15:$AN15) -> 6325262.6
A16: =Assumptions!A35 -> Non Alcoholic Beverage Cost (% of Revenue) | F16: =SUM('Monthly P&L'!$H16:$P16) -> 1246617.9 | G16: =SUM('Monthly P&L'!$Q16:$AB16) -> 2309307.4 | H16: =SUM('Monthly P&L'!$AC16:$AN16) -> 3363439.6
A17: =Assumptions!A36 -> Food Cost (% of Revenue) | F17: =SUM('Monthly P&L'!$H17:$P17) -> 4468789.8 | G17: =SUM('Monthly P&L'!$Q17:$AB17) -> 8227239.6 | H17: =SUM('Monthly P&L'!$AC17:$AN17) -> 11911905
A18: Staff Salary | F18: =SUM('Monthly P&L'!$H18:$P18) -> 8874000 | G18: =SUM('Monthly P&L'!$Q18:$AB18) -> 12896880 | H18: =SUM('Monthly P&L'!$AC18:$AN18) -> 14444506
A19: Total Direct Expenses | F19: =SUM(F15:F18) -> 16849889 | G19: =SUM(G15:G18) -> 27699112 | H19: =SUM(H15:H18) -> 36045113
A21: Less: Indirect Expenses
A22: Other Staff Salary | F22: =SUM('Monthly P&L'!$H22:$P22) -> 3420000 | G22: =SUM('Monthly P&L'!$Q22:$AB22) -> 5073000 | H22: =SUM('Monthly P&L'!$AC22:$AN22) -> 5833950
A23: =Assumptions!A65 -> Royalty to Brand (% of Revenue) | F23: =SUM('Monthly P&L'!$H23:$P23) -> 1223551.4 | G23: =SUM('Monthly P&L'!$Q23:$AB23) -> 2269253.6 | H23: =SUM('Monthly P&L'!$AC23:$AN23) -> 3309356.4
A24: =Assumptions!A66 -> Rent (% of Revenue) | F24: =SUM('Monthly P&L'!$H24:$P24) -> 2447102.8 | G24: =SUM('Monthly P&L'!$Q24:$AB24) -> 4538507.2 | H24: =SUM('Monthly P&L'!$AC24:$AN24) -> 6618712.8
A25: =Assumptions!A67 -> Water Cost/M | F25: =SUM('Monthly P&L'!$H25:$P25) -> 90000 | G25: =SUM('Monthly P&L'!$Q25:$AB25) -> 133500 | H25: =SUM('Monthly P&L'!$AC25:$AN25) -> 153525
A26: =Assumptions!A68 -> Maintenance/M | F26: =SUM('Monthly P&L'!$H26:$P26) -> 450000 | G26: =SUM('Monthly P&L'!$Q26:$AB26) -> 667500 | H26: =SUM('Monthly P&L'!$AC26:$AN26) -> 767625
A27: =Assumptions!A69 -> Marketing Cost/M | F27: =SUM('Monthly P&L'!$H27:$P27) -> 225000 | G27: =SUM('Monthly P&L'!$Q27:$AB27) -> 333750 | H27: =SUM('Monthly P&L'!$AC27:$AN27) -> 383812.5
A28: =Assumptions!A70 -> Electricity (Based on Area $/sq. Ft) | F28: =SUM('Monthly P&L'!$H28:$P28) -> 239400 | G28: =SUM('Monthly P&L'!$Q28:$AB28) -> 355110 | H28: =SUM('Monthly P&L'!$AC28:$AN28) -> 408376.5
A29: =Assumptions!A71 -> Phone & Internet/M | F29: =SUM('Monthly P&L'!$H29:$P29) -> 135000 | G29: =SUM('Monthly P&L'!$Q29:$AB29) -> 200250 | H29: =SUM('Monthly P&L'!$AC29:$AN29) -> 230287.5
A30: =Assumptions!A72 -> Housekeeping & Consumables (% of Revenue) | F30: =SUM('Monthly P&L'!$H30:$P30) -> 489420.56 | G30: =SUM('Monthly P&L'!$Q30:$AB30) -> 907701.44 | H30: =SUM('Monthly P&L'!$AC30:$AN30) -> 1323742.6
A31: =Assumptions!A73 -> Payment Settlement Charges (% of Revenue) | F31: =SUM('Monthly P&L'!$H31:$P31) -> 183532.71 | G31: =SUM('Monthly P&L'!$Q31:$AB31) -> 340388.04 | H31: =SUM('Monthly P&L'!$AC31:$AN31) -> 496403.46
A32: Total Indirect Expenses | F32: =SUM(F22:F31) -> 8903007.5 | G32: =SUM(G22:G31) -> 14818960 | H32: =SUM(H22:H31) -> 19525792
A34: EBITDA | F34: =F12-F19-F32 -> -1281868.2 | G34: =G12-G19-G32 -> 2866999.8 | H34: =H12-H19-H32 -> 10616223
A35: Less: Depreciation | F35: =SUM('Fixed Assets Schedule'!E12,'Fixed Assets Schedule'!E19,'Fixed Assets Schedule'!E26,'Fixed Assets Schedule'!E34) -> 1727753.4 | G35: =SUM('Fixed Assets Schedule'!F12,'Fixed Assets Schedule'!F19,'Fixed Assets Schedule'!F26,'Fixed Assets Schedule'!F34) -> 2092347.9 | H35: =SUM('Fixed Assets Schedule'!G12,'Fixed Assets Schedule'!G19,'Fixed Assets Schedule'!G26,'Fixed Assets Schedule'!G34) -> 1829844.7
A37: EBIT | F37: =F34-F35 -> -3009621.6 | G37: =G34-G35 -> 774651.86 | H37: =H34-H35 -> 8786378.8
A38: Less: Debt Interest | F38: 0 | G38: 0 | H38: 0
A40: EBT | F40: =F37-F38 -> -3009621.6 | G40: =G37-G38 -> 774651.86 | H40: =H37-H38 -> 8786378.8
A41: Less: Taxes | F41: =Assumptions!B124 -> 0.2517 | G41: =F41 -> 0.2517 | H41: =G41 -> 0.2517
A43: EAT/Net Profit | F43: =F40-(F40*F41) -> -2252099.8 | G43: =G40-(G40*G41) -> 579671.99 | H43: =H40-(H40*H41) -> 6574847.2
A44: Transfer to Reserves
A46: Net Profit Margin | F46: =F43/F12 -> -0.092031271 | G46: =G43/G12 -> 0.012772305 | H46: =H43/H12 -> 0.099337249
A50: End of Sheet

Sheet Balance Sheet
D2: Balance Sheet
A4: All Values in: | B4: KSh
E5: 1 | F5: 2 | G5: 3
E6: =EOMONTH(Assumptions!C5,11) -> 44286 | F6: =EOMONTH(E6,12) -> 44651 | G6: =EOMONTH(F6,12) -> 45016
A8: Equity & Liabilities
A9: Equity: | B9: Share Capital | E9: ='Capital Structure'!D18 -> 22500000 | F9: =E9 -> 22500000 | G9: =F9 -> 22500000
B10: Profit Reserves | E10: =D10+'Annual P&L'!F43 -> -2252099.8 | F10: =E10+'Annual P&L'!G43 -> -1672427.8 | G10: =F10+'Annual P&L'!H43 -> 4902419.4
A11: Total Equity Capital | E11: =SUM(E9:E10) -> 20247900 | F11: =SUM(F9:F10) -> 20827572 | G11: =SUM(G9:G10) -> 27402419
A13: Liabilities:
A14: Current Liabilities: | B14: ='Working Capital'!A15 -> Creditor for R/Mtrls | E14: ='Working Capital'!E15 -> 1045753.1 | F14: ='Working Capital'!F15 -> 1369277.3 | G14: ='Working Capital'!G15 -> 1757930.4
B15: ='Working Capital'!A16 -> Creditor for Expenses: | E15: ='Working Capital'!E16 -> 0 | F15: ='Working Capital'!F16 -> 0 | G15: ='Working Capital'!G16 -> 0
B16: ='Working Capital'!A17 -> Alcoholic Beverages | E16: ='Working Capital'!E17 -> 279222.26 | F16: ='Working Capital'!F17 -> 415345.33 | G16: ='Working Capital'!G17 -> 578368.25
B17: ='Working Capital'!A18 -> Non-alcoholic Beverages | E17: ='Working Capital'!E18 -> 154787.9 | F17: ='Working Capital'!F18 -> 225558.72 | G17: ='Working Capital'!G18 -> 311685.04
B18: ='Working Capital'!A19 -> Food | E18: ='Working Capital'!E19 -> 555820.37 | F18: ='Working Capital'!F19 -> 804432.99 | G18: ='Working Capital'!G19 -> 1109283.9
A19: Total Current Liabilities | E19: =SUM(E14:E18) -> 2035583.6 | F19: =SUM(F14:F18) -> 2814614.3 | G19: =SUM(G14:G18) -> 3757267.5
A21: Total Equity & Liabilities | E21: =E11+E19 -> 22283484 | F21: =F11+F19 -> 23642186 | G21: =G11+G19 -> 31159687
A24: Assets
A25: Fixed Assets: | B25: Kitchen Eq. & Cutlery | E25: ='Fixed Assets Schedule'!E13 -> 2663424.7 | F25: ='Fixed Assets Schedule'!F13 -> 2263911 | G25: ='Fixed Assets Schedule'!G13 -> 1924324.3
B26: Refridgeration | E26: ='Fixed Assets Schedule'!E20 -> 4439041.1 | F26: ='Fixed Assets Schedule'!F20 -> 3773184.9 | G26: ='Fixed Assets Schedule'!G20 -> 3207207.2
B27: Furniture | E27: ='Fixed Assets Schedule'!E27 -> 4718547.9 | F27: ='Fixed Assets Schedule'!F27 -> 4246693.2 | G27: ='Fixed Assets Schedule'!G27 -> 3822023.8
B28: Restaurants Décor | E28: ='Fixed Assets Schedule'!E35 -> 5551232.9 | F28: ='Fixed Assets Schedule'!F35 -> 4996109.6 | G28: ='Fixed Assets Schedule'!G35 -> 4496498.6
A29: Total | E29: =SUM(E25:E28) -> 17372247 | F29: =SUM(F25:F28) -> 15279899 | G29: =SUM(G25:G28) -> 13450054
B30: Rent Deposit | E30: ='Capital Structure'!D15 -> 1000000 | F30: =E30 -> 1000000 | G30: =F30 -> 1000000
A31: Total Fixed Assets | E31: =E29+E30 -> 18372247 | F31: =F29+F30 -> 16279899 | G31: =G29+G30 -> 14450054
A33: Current Assets: | B33: ='Working Capital'!A8 -> Alcoholic Beverages | E33: ='Working Capital'!E8 -> 279222.26 | F33: ='Working Capital'!F8 -> 415345.33 | G33: ='Working Capital'!G8 -> 578368.25
B34: ='Working Capital'!A9 -> Non-Alcoholic Beverages | E34: ='Working Capital'!E9 -> 77393.948 | F34: ='Working Capital'!F9 -> 112779.36 | G34: ='Working Capital'!G9 -> 155842.52
B35: ='Working Capital'!A10 -> Food | E35: ='Working Capital'!E10 -> 92636.728 | F35: ='Working Capital'!F10 -> 134072.16 | G35: ='Working Capital'!G10 -> 184880.65
B36: Cash & Cash Equivalents | E36: ='Cash Flow Statement'!E31 -> 3461984.3 | F36: ='Cash Flow Statement'!F31 -> 6700091 | G36: ='Cash Flow Statement'!G31 -> 15790542
A37: Total Current Assets | E37: =SUM(E33:E36) -> 3911237.2 | F37: =SUM(F33:F36) -> 7362287.9 | G37: =SUM(G33:G36) -> 16709633
A39: Total Assets | E39: =E31+E37 -> 22283484 | F39: =F31+F37 -> 23642186 | G39: =G31+G37 -> 31159687
A42: Checker | E42: =E21-E39 -> 0 | F42: =F21-F39 -> 0 | G42: =G21-G39 -> 0
A46: End of Sheet

Sheet Cash Flow Statement
D3: Cash Flow Statement
A4: All Values in: | B4: KSh
E5: 1 | F5: 2 | G5: 3
E6: =EOMONTH(Assumptions!C5,11) -> 44286 | F6: =EOMONTH(E6,12) -> 44651 | G6: =EOMONTH(F6,12) -> 45016
A8: Operating Activities
A9: EAT/Net Profit | E9: ='Annual P&L'!F43 -> -2252099.8 | F9: ='Annual P&L'!G43 -> 579671.99 | G9: ='Annual P&L'!H43 -> 6574847.2
A10: Add: Non Cash Items:
A11: Depreciation | E11: ='Annual P&L'!F35 -> 1727753.4 | F11: ='Annual P&L'!G35 -> 2092347.9 | G11: ='Annual P&L'!H35 -> 1829844.7
A12: Less: Changes in Working Capital | E12: ='Working Capital'!E25 -> 1586330.7 | F12: ='Working Capital'!F25 -> 566086.8 | G12: ='Working Capital'!G25 -> 685758.65
A14: Net Cash Flows from Operating Activities | E14: =E9+E11+E12 -> 1061984.3 | F14: =F9+F11+F12 -> 3238106.7 | G14: =G9+G11+G12 -> 9090450.5
A16: Investing Activities
A17: Purchase of Fixed Assets | E17: =-'Capital Structure'!D13 -> -19100000 | F17: 0 | G17: 0
A18: Rent Deposits | E18: =-'Capital Structure'!D15 -> -1000000 | F18: 0 | G18: 0
A20: Net CashFlows from Investing Activities | E20: =E17+E18 -> -20100000 | F20: =F17+F18 -> 0 | G20: =G17+G18 -> 0
A22: Financing Activities
A23: Equity Share Capital | E23: ='Capital Structure'!D21 -> 22500000 | F23: 0 | G23: 0
A24: Debt Share Capital | E24: ='Capital Structure'!D22 -> 0 | F24: 0 | G24: 0
A26: Net Cash Flows from Financing Activities | E26: =E23+E24 -> 22500000 | F26: =F23+F24 -> 0 | G26: =G23+G24 -> 0
A28: Net Cash Flows for the Period | E28: =E14+E20+E26 -> 3461984.3 | F28: =F14+F20+F26 -> 3238106.7 | G28: =G14+G20+G26 -> 9090450.5
A29: Add: Opening Balance | E29: 0 | F29: =E31 -> 3461984.3 | G29: =F31 -> 6700091
A31: Closing Blance for the Period | E31: =E28+E29 -> 3461984.3 | F31: =F28+F29 -> 6700091 | G31: =G28+G29 -> 15790542
A34: End of Sheet
